<?xml version="1.0" ?>

<robot name="rumba_like_robot" xmlns:xacro="http://wwww.ros.org/wiki/xacro">

    <link name="robot_footprint">
        
    </link>

    <xacro:include filename="$(find rumba_like_robot)/urdf/robot_rumba.gazebo" />

    <joint name="robot_footprint_joint" type="fixed">
        <origin xyz="0 0 0.0" rpy="0 0 0"/>
        <parent link="robot_footprint"/>
        <child link="chassis"/>
        
    </joint>
    <!-- chassis aka link_0 -->
    <link name="chassis"> 
        <pose>0.0 0.0 0.0 0.0 0.0 0.0 </pose>
        <inertial>
            <mass value="15.0"/>
            <origin xyz="0.0 0.0 0.2" rpy="0 0 0" />
            <inertia ixx="0.1" ixy="0.0" ixz="0.0"
                     iyy="0.1" iyz="0.0"
                     izz="0.1" />
        </inertial>
        
        <collision name="collision">
            <origin xyz="0.0 0.0 0.2" rpy="0 0 0"/>
            <geometry>
                <cylinder radius="0.5" length="0.2"/>
            </geometry>

        </collision>

        <visual name="chassis_visual">
            <origin xyz="0.0 0.0 0.2" rpy="0.0 0.0 0.0"/>
            <geometry>
                <cylinder radius="0.5" length="0.2"/> 
            </geometry>
            
        </visual>

        <!-- <collision name="back_caster_collision">
            <origin xyz="-0.15 0.0 -0.05" rpy="0.0 0.0 0.0"/>
            <geometry>
                <sphere radius="0.2"/>
            </geometry>
            
        </collision>

        <visual name="back_caster_visual">
            <origin xyz="-0.15 0.0 -0.05"/>
            <geometry>
                <sphere radius="0.05"/>
            </geometry>
            
        </visual>

        <collision name="front_caster_collision">
            <origin xyz="0.15 0.0 -0.05" rpy="0.0 0.0 0.0"/>
            <geometry>
                <sphere radius="0.0499"/>
            </geometry>
            
        </collision>

        <visual name="front_caster_visual">
            <origin xyz="0.15 0.0 -0.05" rpy="0.0 0.0 0.0"/>
            <geometry>
                <sphere radius="0.05"/>
            </geometry>
            
        </visual> -->
    </link>

    <link name="right_wheel">
        <inertial>
            <mass value="2.5"/>
            <origin xyz="0.0 0.0 0.0" rpy="0.0 0 0"/>
            <geometry>
                <sphere radius="0.1"/>
            </geometry>
           <inertia ixx="0.1" ixy="0.0" ixz="0.0" iyy="0.1" iyz="0.0" izz="0.1"/>
    
        </inertial>
        
        <collision>
            <origin xyz="0.0 0.0 0.0" rpy="0.0 0.0 0.0"/>
            <geometry>
                <sphere radius="0.1"/>
            </geometry>
            
        </collision>

        <visual name="right_wheel_visual">
            <origin xyz="0.0 0.0 0.0" rpy="0.0 0.0 0.0"/>
            <geometry>
                <sphere radius="0.1"/>
            </geometry>
            
        </visual>
    </link>

    <link name="left_wheel">
        <inertial>
            <mass value="2.5"/>
            <origin xyz="0.0 0.0 0.0" rpy="0.0 0.0 0.0"/>
            <geometry>
                <sphere radius="0.1"/>
            </geometry>
           <inertia ixx="0.1" ixy="0.0" ixz="0.0" iyy="0.1" iyz="0.0" izz="0.1"/>
        </inertial>

        <collision>
            <origin xyz="0.0 0.0 0.0" rpy="0.0 0.0 0.0"/>
            <geometry>
                <sphere radius="0.1"/>
            </geometry>
        </collision>

        <visual name="left_wheel_visual">
            <origin xyz="0.0 0.0 0.0" rpy="0.0 0.0 0.0"/>
            <geometry>
                <sphere radius="0.1"/>
            </geometry>
            
        </visual>
        
    </link>
    
    <link name="back_wheel">
        <inertial>
            <mass value="2.5"/>
            <origin xyz="0.0 0.0 0.0" rpy="0.0 0.0 0.0"/>
            <geometry>
                <sphere radius="0.1"/>
            </geometry>
           <inertia ixx="0.1" ixy="0.0" ixz="0.0" iyy="0.1" iyz="0.0" izz="0.1"/>
        </inertial>

        <collision>
            <origin xyz="0.0 0.0 0.0" rpy="0.0 0.0 0.0"/>
            <geometry>
                <sphere radius="0.1"/>
            </geometry>
        </collision>

        <visual name="back_wheel_visual">
            <origin xyz="0.0 0.0 0.0" rpy="0.0 0.0 0.0"/>
            <geometry>
                <sphere radius="0.1"/>
            </geometry>
            
        </visual>
        
    </link>


    <link name="front_wheel">
        <inertial>
            <mass value="2.5"/>
            <origin xyz="0.0 0.0 0.0" rpy="0.0 0.0 0.0"/>
            <geometry>
                <sphere radius="0.1"/>
            </geometry>
           <inertia ixx="0.1" ixy="0.0" ixz="0.0" iyy="0.1" iyz="0.0" izz="0.1"/>
        </inertial>

        <collision>
            <origin xyz="0.0 0.0 0.0" rpy="0.0 0.0 0.0"/>
            <geometry>
                <sphere radius="0.1"/>
            </geometry>
        </collision>

        <visual name="front_wheel_visual">
            <origin xyz="0.0 0.0 0.0" rpy="0.0 0.0 0.0"/>
            <geometry>
                <sphere radius="0.1"/>
            </geometry>
            
        </visual>
        
    </link>

    <!--  left wheel spherical joint -->
    <joint name="left_wheel_hinge" type="continuous">
        <origin xyz="0.0 0.35 0.1" rpy="0.0 0.0 0.0"/>
        <parent link="chassis"/>
        <child link="left_wheel"/>
        <axis xyz="0.0 1.0 0.0" rpy="0.0 0.0 0.0"/>
        <limit effort="10000" velocity="1000"/>/
        <dynamics damping="1.0" friction="1.0"/>
    </joint>
    <!-- <link name="left_wheel_y"/>
    <link name="left_wheel_z"/>
    <link name="left_wheel_x"/>
    <joint name="left_wheel_hinge_y" type="continuous">
      
        <parent link="left_wheel_hinge"/>
        <child link="left_wheel_y"/>
        <axis xyz="0.0 1.0 0.0" rpy="0.0 0.0 0.0"/>
        <limit effort="10000" velocity="1000"/>
        <dynamics damping="1.0" friction="1.0"/>
    </joint>
    <joint name="left_wheel_hinge_z" type="continuous">
       
        <parent link="left_wheel_hinge"/>
        <child link="left_wheel_z"/>
        <axis xyz="0.0 0.0 1.0" rpy="0.0 0.0 0.0"/>
        <limit effort="10000" velocity="1000"/>
        <dynamics damping="1.0" friction="1.0"/>
    </joint>
    <joint name="left_wheel_hinge_x" type="continuous">
        
        <parent link="left_wheel_hinge"/>
        <child link="left_wheel_x"/>
        <axis xyz="1.0 0.0 0.0" rpy="0.0 0.0 0.0"/>
        <limit effort="10000" velocity="1000"/>
        <dynamics damping="1.0" friction="1.0"/>
    </joint> -->


    <!--  Right wheel spherical joint -->
    <joint name="right_wheel_hinge" type="continuous">
        <origin xyz="0.0 -0.35 0.1" rpy="0.0 0.0 0.0"/>
        <parent link="chassis"/>
        <child link="right_wheel"/>
        <axis xyz="0.0 1.0 1.0" rpy="0.0 0.0 0.0"/>
        <limit effort="10000" velocity="1000"/>
        <dynamics damping="1.0" friction="1.0" />

    </joint>
    <!--  back wheel spherical joint -->
    <joint name="back_wheel_hinge" type="continuous">
        <origin xyz="-0.35 0.0 0.1" rpy="0.0 0.0 0.0"/>
        <parent link="chassis"/>
        <child link="back_wheel"/>
        <axis xyz="0.0 1.0 1.0" rpy="0.0 0.0 0.0"/>
        <limit effort="10000" velocity="1000"/>
        <dynamics damping="1.0" friction="1.0"/>
        
        
    </joint>

    <!--  front wheel spherical joint -->
    <joint name="front_wheel_hinge" type="continuous">
        <origin xyz="0.35 0.0 0.1" rpy="0.0 0.0 0.0"/>
        <parent link="chassis"/>
        <child link="front_wheel"/>
        <axis xyz="0.0 1.0 0.0" rpy="0.0 0.0 0.0"/>
        <limit effort="10000" velocity="1000"/>
        <dynamics damping="1.0" friction="1.0" />

    </joint>

    <link name="camera">
        <inertial>
            <mass value="0.2"/>
            <origin xyz="0.0 0.0 0.0" rpy="0.0 0.0 0.0"/>
            <geometry>
                <box size="0.05 0.05 0.05" />
                <box_inertia m="0.1" x="0.05" y="0.05" z="0.05"/>
            </geometry>
            <inertia ixx="1e-6" ixy="0.0" ixz="0.0" iyy="1e-6" iyz="0.0" izz="1e-6"/>
        </inertial>
        <collision>
            <origin xyz="0.0 0.0 0.0" rpy="0.0 0.0 0.0"/>
            <geometry>
                <box size="0.05 0.05 0.05"/>
                <box_inertia m="0.1" x="0.05" y="0.05" z="0.05"/>
            </geometry>
            
        </collision>

        <visual name="camera_visual">
            <origin xyz="0.0 0.0 0.0" rpy="0.0 0.0 0.0"/>
            <geometry>
                <box size="0.05 0.05 0.05"/>
                <box_inertia m="0.1" x="0.05" y="0.05" z="0.05"/>
            </geometry>
            
        </visual>
        
    </link>

    <joint name="camera_joint" type="fixed">
        <axis xyz="0.0 1 0.0"/>
        <origin xyz="0.5 0.0 0.2" rpy="0.0 0.0 0.0"/>
        <parent link="chassis"/>
        <child link="camera"/>
        
        
    </joint>

    <link name="hokuyo">
        <inertial>
            <mass value="1e-5"/>
            <origin xyz="0.0 0.0 0.0" rpy="0.0 0.0 0.0"/>
            <geometry>
                <box size="0.1 0.1 0.1"/>
            </geometry>
            <inertia ixx="1e-6" ixy="0.0" ixz="0.0" iyy="1e-6" iyz="0.0" izz="1e-6"/>
        </inertial>

        <collision>
            <origin xyz="0.0 0.0 0.0" rpy="0.0 0.0 0.0"/>
            <geometry>
                <box size="0.1 0.1 0.1"/>
            </geometry>
        </collision>

        <visual name="hokuyo_lidar_visual">
            <origin xyz="0.0 0.0 0.0" rpy="0.0 0.0 0.0"/>
            <geometry>
                <mesh filename="package://rumba_like_robot/meshes/hokuyo.dae"/>
            </geometry>
            
        </visual>
        
    </link>

    <joint name="hokuyo_lidar_joint" type="fixed">
        <axis xyz="0.0 1.0 0.0"/>
        <origin xyz="0.45 0.0 0.3" rpy="0.0 0.0 0.0"/>
        <parent link="chassis"/>
        <child link="hokuyo"/>
        
        
    </joint>

    <gazebo reference="left_wheel">
        <material>Gazebo/Green</material>
    </gazebo>

    <gazebo reference="right_wheel">
        <material>Gazebo/Green</material>
    </gazebo>
    <gazebo reference="front_wheel">
        <material>Gazebo/Green</material>
    </gazebo>

    <gazebo reference="back_wheel">
        <material>Gazebo/Green</material>
    </gazebo>

    <gazebo reference="chassis">
        <material>Gazebo/Yellow</material>
    </gazebo>

    <gazebo reference="camera">
        <material>Gazebo/Red</material>
    </gazebo>
    
    <!-- <gazebo reference="hokuyo">
        <material>Gazebo/Purple</material>
    </gazebo> -->
    
</robot>